[2024-12-10T13:14:45.670+0000] {local_task_job_runner.py:123} INFO - ::group::Pre task execution logs
[2024-12-10T13:14:45.723+0000] {taskinstance.py:2612} INFO - Dependencies all met for dep_context=non-requeueable deps ti=<TaskInstance: etl_rides_pipeline.extract_rides scheduled__2024-11-13T00:00:00+00:00 [queued]>
[2024-12-10T13:14:45.742+0000] {taskinstance.py:2612} INFO - Dependencies all met for dep_context=requeueable deps ti=<TaskInstance: etl_rides_pipeline.extract_rides scheduled__2024-11-13T00:00:00+00:00 [queued]>
[2024-12-10T13:14:45.743+0000] {taskinstance.py:2865} INFO - Starting attempt 1 of 2
[2024-12-10T13:14:45.780+0000] {taskinstance.py:2888} INFO - Executing <Task(PythonOperator): extract_rides> on 2024-11-13 00:00:00+00:00
[2024-12-10T13:14:45.798+0000] {standard_task_runner.py:72} INFO - Started process 314 to run task
[2024-12-10T13:14:45.813+0000] {standard_task_runner.py:104} INFO - Running: ['***', 'tasks', 'run', 'etl_rides_pipeline', 'extract_rides', 'scheduled__2024-11-13T00:00:00+00:00', '--job-id', '131', '--raw', '--subdir', 'DAGS_FOLDER/etl_dag.py', '--cfg-path', '/tmp/tmpfpzkbn0h']
[2024-12-10T13:14:45.824+0000] {standard_task_runner.py:105} INFO - Job 131: Subtask extract_rides
[2024-12-10T13:14:46.087+0000] {task_command.py:467} INFO - Running <TaskInstance: etl_rides_pipeline.extract_rides scheduled__2024-11-13T00:00:00+00:00 [running]> on host 8c16ff7970b8
[2024-12-10T13:14:46.791+0000] {taskinstance.py:3131} INFO - Exporting env vars: AIRFLOW_CTX_DAG_OWNER='axel' AIRFLOW_CTX_DAG_ID='etl_rides_pipeline' AIRFLOW_CTX_TASK_ID='extract_rides' AIRFLOW_CTX_EXECUTION_DATE='2024-11-13T00:00:00+00:00' AIRFLOW_CTX_TRY_NUMBER='1' AIRFLOW_CTX_DAG_RUN_ID='scheduled__2024-11-13T00:00:00+00:00'
[2024-12-10T13:14:46.796+0000] {logging_mixin.py:190} INFO - Task instance is in running state
[2024-12-10T13:14:46.798+0000] {logging_mixin.py:190} INFO -  Previous state of the Task instance: queued
[2024-12-10T13:14:46.799+0000] {logging_mixin.py:190} INFO - Current task name:extract_rides state:running start_date:2024-12-10 13:14:45.726189+00:00
[2024-12-10T13:14:46.801+0000] {logging_mixin.py:190} INFO - Dag name:etl_rides_pipeline and current dag run status:running
[2024-12-10T13:14:46.804+0000] {taskinstance.py:731} INFO - ::endgroup::
[2024-12-10T13:14:58.840+0000] {taskinstance.py:3310} ERROR - Task failed with exception
Traceback (most recent call last):
  File "/home/airflow/.local/lib/python3.11/site-packages/sqlalchemy/engine/base.py", line 1910, in _execute_context
    self.dialect.do_execute(
  File "/home/airflow/.local/lib/python3.11/site-packages/sqlalchemy/engine/default.py", line 736, in do_execute
    cursor.execute(statement, parameters)
psycopg2.errors.UndefinedTable: relation "rides" does not exist
LINE 1: SELECT * FROM rides WHERE tpep_pickup_datetime >= '2024-01-0...
                      ^


The above exception was the direct cause of the following exception:

Traceback (most recent call last):
  File "/home/airflow/.local/lib/python3.11/site-packages/airflow/models/taskinstance.py", line 767, in _execute_task
    result = _execute_callable(context=context, **execute_callable_kwargs)
             ^^^^^^^^^^^^^^^^^^^^^^^^^^^^^^^^^^^^^^^^^^^^^^^^^^^^^^^^^^^^^
  File "/home/airflow/.local/lib/python3.11/site-packages/airflow/models/taskinstance.py", line 733, in _execute_callable
    return ExecutionCallableRunner(
           ^^^^^^^^^^^^^^^^^^^^^^^^
  File "/home/airflow/.local/lib/python3.11/site-packages/airflow/utils/operator_helpers.py", line 252, in run
    return self.func(*args, **kwargs)
           ^^^^^^^^^^^^^^^^^^^^^^^^^^
  File "/home/airflow/.local/lib/python3.11/site-packages/airflow/models/baseoperator.py", line 406, in wrapper
    return func(self, *args, **kwargs)
           ^^^^^^^^^^^^^^^^^^^^^^^^^^^
  File "/home/airflow/.local/lib/python3.11/site-packages/airflow/operators/python.py", line 238, in execute
    return_value = self.execute_callable()
                   ^^^^^^^^^^^^^^^^^^^^^^^
  File "/home/airflow/.local/lib/python3.11/site-packages/airflow/operators/python.py", line 256, in execute_callable
    return runner.run(*self.op_args, **self.op_kwargs)
           ^^^^^^^^^^^^^^^^^^^^^^^^^^^^^^^^^^^^^^^^^^^
  File "/home/airflow/.local/lib/python3.11/site-packages/airflow/utils/operator_helpers.py", line 252, in run
    return self.func(*args, **kwargs)
           ^^^^^^^^^^^^^^^^^^^^^^^^^^
  File "/opt/airflow/dags/etl_dag.py", line 15, in extract_rides
    rides_data = pd.read_sql(query, engine)
                 ^^^^^^^^^^^^^^^^^^^^^^^^^^
  File "/home/airflow/.local/lib/python3.11/site-packages/pandas/io/sql.py", line 682, in read_sql
    return pandas_sql.read_query(
           ^^^^^^^^^^^^^^^^^^^^^^
  File "/home/airflow/.local/lib/python3.11/site-packages/pandas/io/sql.py", line 1776, in read_query
    result = self.execute(sql, params)
             ^^^^^^^^^^^^^^^^^^^^^^^^^
  File "/home/airflow/.local/lib/python3.11/site-packages/pandas/io/sql.py", line 1599, in execute
    return self.con.exec_driver_sql(sql, *args)
           ^^^^^^^^^^^^^^^^^^^^^^^^^^^^^^^^^^^^
  File "/home/airflow/.local/lib/python3.11/site-packages/sqlalchemy/engine/base.py", line 1770, in exec_driver_sql
    return self._exec_driver_sql(
           ^^^^^^^^^^^^^^^^^^^^^^
  File "/home/airflow/.local/lib/python3.11/site-packages/sqlalchemy/engine/base.py", line 1674, in _exec_driver_sql
    ret = self._execute_context(
          ^^^^^^^^^^^^^^^^^^^^^^
  File "/home/airflow/.local/lib/python3.11/site-packages/sqlalchemy/engine/base.py", line 1953, in _execute_context
    self._handle_dbapi_exception(
  File "/home/airflow/.local/lib/python3.11/site-packages/sqlalchemy/engine/base.py", line 2134, in _handle_dbapi_exception
    util.raise_(
  File "/home/airflow/.local/lib/python3.11/site-packages/sqlalchemy/util/compat.py", line 211, in raise_
    raise exception
  File "/home/airflow/.local/lib/python3.11/site-packages/sqlalchemy/engine/base.py", line 1910, in _execute_context
    self.dialect.do_execute(
  File "/home/airflow/.local/lib/python3.11/site-packages/sqlalchemy/engine/default.py", line 736, in do_execute
    cursor.execute(statement, parameters)
sqlalchemy.exc.ProgrammingError: (psycopg2.errors.UndefinedTable) relation "rides" does not exist
LINE 1: SELECT * FROM rides WHERE tpep_pickup_datetime >= '2024-01-0...
                      ^

[SQL: SELECT * FROM rides WHERE tpep_pickup_datetime >= '2024-01-01']
(Background on this error at: https://sqlalche.me/e/14/f405)
[2024-12-10T13:15:04.582+0000] {logging_mixin.py:190} INFO - Task instance in failure state
[2024-12-10T13:15:04.649+0000] {logging_mixin.py:190} INFO - Task start:2024-12-10 13:14:45.726189+00:00 end:2024-12-10 13:15:04.572455+00:00 duration:18.846266
[2024-12-10T13:15:04.668+0000] {logging_mixin.py:190} INFO - Task:<Task(PythonOperator): extract_rides> dag:<DAG: etl_rides_pipeline> dagrun:<DagRun etl_rides_pipeline @ 2024-11-13 00:00:00+00:00: scheduled__2024-11-13T00:00:00+00:00, state:running, queued_at: 2024-12-10 13:14:04.359497+00:00. externally triggered: False>
[2024-12-10T13:15:04.680+0000] {logging_mixin.py:190} INFO - Failure caused by (psycopg2.errors.UndefinedTable) relation "rides" does not exist
LINE 1: SELECT * FROM rides WHERE tpep_pickup_datetime >= '2024-01-0...
                      ^

[SQL: SELECT * FROM rides WHERE tpep_pickup_datetime >= '2024-01-01']
(Background on this error at: https://sqlalche.me/e/14/f405)
[2024-12-10T13:15:04.685+0000] {taskinstance.py:1225} INFO - Marking task as UP_FOR_RETRY. dag_id=etl_rides_pipeline, task_id=extract_rides, run_id=scheduled__2024-11-13T00:00:00+00:00, execution_date=20241113T000000, start_date=20241210T131445, end_date=20241210T131504
[2024-12-10T13:15:06.949+0000] {standard_task_runner.py:217} INFO - Process not found (most likely exited), stop collecting metrics
[2024-12-10T13:15:06.941+0000] {local_task_job_runner.py:266} INFO - Task exited with return code -9For more information, see https://***.apache.org/docs/apache-***/stable/troubleshooting.html#LocalTaskJob-killed
[2024-12-10T13:15:07.312+0000] {taskinstance.py:3900} INFO - 0 downstream tasks scheduled from follow-on schedule check
[2024-12-10T13:15:07.382+0000] {local_task_job_runner.py:245} INFO - ::endgroup::
