[2024-11-21T12:26:26.951+0000] {local_task_job_runner.py:123} INFO - ::group::Pre task execution logs
[2024-11-21T12:26:27.159+0000] {taskinstance.py:2612} INFO - Dependencies all met for dep_context=non-requeueable deps ti=<TaskInstance: etl_rides_pipeline.extract_rides scheduled__2024-02-05T00:00:00+00:00 [queued]>
[2024-11-21T12:26:27.199+0000] {taskinstance.py:2612} INFO - Dependencies all met for dep_context=requeueable deps ti=<TaskInstance: etl_rides_pipeline.extract_rides scheduled__2024-02-05T00:00:00+00:00 [queued]>
[2024-11-21T12:26:27.202+0000] {taskinstance.py:2865} INFO - Starting attempt 2 of 2
[2024-11-21T12:26:27.267+0000] {taskinstance.py:2888} INFO - Executing <Task(PythonOperator): extract_rides> on 2024-02-05 00:00:00+00:00
[2024-11-21T12:26:27.345+0000] {standard_task_runner.py:72} INFO - Started process 424 to run task
[2024-11-21T12:26:27.389+0000] {standard_task_runner.py:104} INFO - Running: ['***', 'tasks', 'run', 'etl_rides_pipeline', 'extract_rides', 'scheduled__2024-02-05T00:00:00+00:00', '--job-id', '83', '--raw', '--subdir', 'DAGS_FOLDER/etl_dag.py', '--cfg-path', '/tmp/tmpks535f8y']
[2024-11-21T12:26:27.400+0000] {standard_task_runner.py:105} INFO - Job 83: Subtask extract_rides
[2024-11-21T12:26:27.927+0000] {task_command.py:467} INFO - Running <TaskInstance: etl_rides_pipeline.extract_rides scheduled__2024-02-05T00:00:00+00:00 [running]> on host 8c16ff7970b8
[2024-11-21T12:26:29.615+0000] {taskinstance.py:3131} INFO - Exporting env vars: AIRFLOW_CTX_DAG_OWNER='axel' AIRFLOW_CTX_DAG_ID='etl_rides_pipeline' AIRFLOW_CTX_TASK_ID='extract_rides' AIRFLOW_CTX_EXECUTION_DATE='2024-02-05T00:00:00+00:00' AIRFLOW_CTX_TRY_NUMBER='2' AIRFLOW_CTX_DAG_RUN_ID='scheduled__2024-02-05T00:00:00+00:00'
[2024-11-21T12:26:29.662+0000] {logging_mixin.py:190} INFO - Task instance is in running state
[2024-11-21T12:26:29.678+0000] {logging_mixin.py:190} INFO -  Previous state of the Task instance: queued
[2024-11-21T12:26:29.686+0000] {logging_mixin.py:190} INFO - Current task name:extract_rides state:running start_date:2024-11-21 12:26:27.167771+00:00
[2024-11-21T12:26:29.696+0000] {logging_mixin.py:190} INFO - Dag name:etl_rides_pipeline and current dag run status:running
[2024-11-21T12:26:29.700+0000] {taskinstance.py:731} INFO - ::endgroup::
[2024-11-21T12:26:42.025+0000] {taskinstance.py:3310} ERROR - Task failed with exception
Traceback (most recent call last):
  File "/home/airflow/.local/lib/python3.11/site-packages/sqlalchemy/engine/base.py", line 1910, in _execute_context
    self.dialect.do_execute(
  File "/home/airflow/.local/lib/python3.11/site-packages/sqlalchemy/engine/default.py", line 736, in do_execute
    cursor.execute(statement, parameters)
psycopg2.errors.UndefinedTable: relation "rides" does not exist
LINE 1: SELECT * FROM rides WHERE tpep_pickup_datetime >= '2024-01-0...
                      ^


The above exception was the direct cause of the following exception:

Traceback (most recent call last):
  File "/home/airflow/.local/lib/python3.11/site-packages/airflow/models/taskinstance.py", line 767, in _execute_task
    result = _execute_callable(context=context, **execute_callable_kwargs)
             ^^^^^^^^^^^^^^^^^^^^^^^^^^^^^^^^^^^^^^^^^^^^^^^^^^^^^^^^^^^^^
  File "/home/airflow/.local/lib/python3.11/site-packages/airflow/models/taskinstance.py", line 733, in _execute_callable
    return ExecutionCallableRunner(
           ^^^^^^^^^^^^^^^^^^^^^^^^
  File "/home/airflow/.local/lib/python3.11/site-packages/airflow/utils/operator_helpers.py", line 252, in run
    return self.func(*args, **kwargs)
           ^^^^^^^^^^^^^^^^^^^^^^^^^^
  File "/home/airflow/.local/lib/python3.11/site-packages/airflow/models/baseoperator.py", line 406, in wrapper
    return func(self, *args, **kwargs)
           ^^^^^^^^^^^^^^^^^^^^^^^^^^^
  File "/home/airflow/.local/lib/python3.11/site-packages/airflow/operators/python.py", line 238, in execute
    return_value = self.execute_callable()
                   ^^^^^^^^^^^^^^^^^^^^^^^
  File "/home/airflow/.local/lib/python3.11/site-packages/airflow/operators/python.py", line 256, in execute_callable
    return runner.run(*self.op_args, **self.op_kwargs)
           ^^^^^^^^^^^^^^^^^^^^^^^^^^^^^^^^^^^^^^^^^^^
  File "/home/airflow/.local/lib/python3.11/site-packages/airflow/utils/operator_helpers.py", line 252, in run
    return self.func(*args, **kwargs)
           ^^^^^^^^^^^^^^^^^^^^^^^^^^
  File "/opt/airflow/dags/etl_dag.py", line 15, in extract_rides
    rides_data = pd.read_sql(query, engine)
                 ^^^^^^^^^^^^^^^^^^^^^^^^^^
  File "/home/airflow/.local/lib/python3.11/site-packages/pandas/io/sql.py", line 682, in read_sql
    return pandas_sql.read_query(
           ^^^^^^^^^^^^^^^^^^^^^^
  File "/home/airflow/.local/lib/python3.11/site-packages/pandas/io/sql.py", line 1776, in read_query
    result = self.execute(sql, params)
             ^^^^^^^^^^^^^^^^^^^^^^^^^
  File "/home/airflow/.local/lib/python3.11/site-packages/pandas/io/sql.py", line 1599, in execute
    return self.con.exec_driver_sql(sql, *args)
           ^^^^^^^^^^^^^^^^^^^^^^^^^^^^^^^^^^^^
  File "/home/airflow/.local/lib/python3.11/site-packages/sqlalchemy/engine/base.py", line 1770, in exec_driver_sql
    return self._exec_driver_sql(
           ^^^^^^^^^^^^^^^^^^^^^^
  File "/home/airflow/.local/lib/python3.11/site-packages/sqlalchemy/engine/base.py", line 1674, in _exec_driver_sql
    ret = self._execute_context(
          ^^^^^^^^^^^^^^^^^^^^^^
  File "/home/airflow/.local/lib/python3.11/site-packages/sqlalchemy/engine/base.py", line 1953, in _execute_context
    self._handle_dbapi_exception(
  File "/home/airflow/.local/lib/python3.11/site-packages/sqlalchemy/engine/base.py", line 2134, in _handle_dbapi_exception
    util.raise_(
  File "/home/airflow/.local/lib/python3.11/site-packages/sqlalchemy/util/compat.py", line 211, in raise_
    raise exception
  File "/home/airflow/.local/lib/python3.11/site-packages/sqlalchemy/engine/base.py", line 1910, in _execute_context
    self.dialect.do_execute(
  File "/home/airflow/.local/lib/python3.11/site-packages/sqlalchemy/engine/default.py", line 736, in do_execute
    cursor.execute(statement, parameters)
sqlalchemy.exc.ProgrammingError: (psycopg2.errors.UndefinedTable) relation "rides" does not exist
LINE 1: SELECT * FROM rides WHERE tpep_pickup_datetime >= '2024-01-0...
                      ^

[SQL: SELECT * FROM rides WHERE tpep_pickup_datetime >= '2024-01-01']
(Background on this error at: https://sqlalche.me/e/14/f405)
[2024-11-21T12:42:56.556+0000] {local_task_job_runner.py:228} ERROR - Heartbeat time limit exceeded!
[2024-11-21T12:42:56.573+0000] {local_task_job_runner.py:245} INFO - ::endgroup::
[2024-11-21T12:42:56.621+0000] {process_utils.py:132} INFO - Sending 15 to group 424. PIDs of all processes in the group: [424]
[2024-11-21T12:42:56.650+0000] {process_utils.py:87} INFO - Sending the signal 15 to group 424
[2024-11-21T12:42:56.785+0000] {taskinstance.py:3092} ERROR - Received SIGTERM. Terminating subprocesses.
[2024-11-21T12:42:56.801+0000] {taskinstance.py:340} INFO - ::group::Post task execution logs
[2024-11-21T12:42:56.869+0000] {process_utils.py:80} INFO - Process psutil.Process(pid=424, status='terminated', exitcode=2, started='12:26:27') (424) terminated with exit code 2
